Workbook

Sheet Fluxo de caixa
C3: Curso Viabilidade de Projetos & Negócios – seleção de alternativas de investimento
B5: Montagem do fluxo de caixa
B7: MÊS 1
B9: Mês | C9: Tipo de item de fluxo | D9: Descrição do item de fluxo | E9: Valor
B10: 1 | C10: Previsão de vendas | D10: Vendas brutas previstas | E10: 0
D11: Total de vendas brutas previstas mês 1 = | E11: =SUM(E10) -> 0
B13: Mês | C13: Tipo de item de fluxo | D13: Descrição do item de fluxo | E13: Valor | F13: Abra quantas linhas necessitar, cuidando de não danificar a totalização
B14: 1 | C14: Despesas variáveis | D14: Compra de matérias-primas | E14: 150
D15: Compra de embalagens | E15: 30
D16: Confecção de folhetos promocionais | E16: 50
D17: Entregas de amostras promocionais | E17: 80
D20: Total de despesas variáveis previstas mês 1 = | E20: =SUM(E14:E19) -> 310
B22: Mês | C22: Tipo de item de fluxo | D22: Descrição do item de fluxo | E22: Valor | F22: Abra quantas linhas necessitar, cuidando de não danificar a totalização
B23: 1 | C23: Despesas fixas | D23: Hospedagem de site | E23: 15
D24: Plataforma de e-commerce | E24: 50
D29: Total de despesas fixas previstas mês 1 = | E29: =SUM(E23:E28) -> 65
C31: Resumo do fluxo no mês 1 | D31: Vendas brutas previstas | E31: =E11 -> 0
D32: Despesas variáveis | E32: =E20 -> 310
D33: Despesas fixas | E33: =E29 -> 65
B36: MÊS 2
B38: Mês | C38: Tipo de item de fluxo | D38: Descrição do item de fluxo | E38: Valor
B39: 2 | C39: Previsão de vendas | D39: Vendas brutas previstas | E39: 400
D40: Total de vendas brutas previstas mês 2 = | E40: =SUM(E39) -> 400
B42: Mês | C42: Tipo de item de fluxo | D42: Descrição do item de fluxo | E42: Valor | F42: Abra quantas linhas necessitar, cuidando de não danificar a totalização
B43: 2 | C43: Despesas variáveis | D43: Compra de matérias-primas | E43: 200
D44: Compra de embalagens | E44: 40
D45: Entregas | E45: 160
D49: Total de despesas variáveis previstas mês 2 = | E49: =SUM(E43:E48) -> 400
B51: Mês | C51: Tipo de item de fluxo | D51: Descrição do item de fluxo | E51: Valor | F51: Abra quantas linhas necessitar, cuidando de não danificar a totalização
B52: 2 | C52: Despesas fixas | D52: Hospedagem de site | E52: 15
D53: Plataforma de e-commerce | E53: 50
D58: Total de despesas fixas previstas mês 2 = | E58: =SUM(E52:E57) -> 65
C60: Resumo do fluxo no mês 2 | D60: Vendas brutas previstas | E60: =E40 -> 400
D61: Despesas variáveis | E61: =E49 -> 400
D62: Despesas fixas | E62: =E58 -> 65
B64: MÊS 3
B66: Mês | C66: Tipo de item de fluxo | D66: Descrição do item de fluxo | E66: Valor
B67: 3 | C67: Previsão de vendas | D67: Vendas brutas previstas | E67: 500
D68: Total de vendas brutas previstas mês 3 = | E68: =SUM(E67) -> 500
B70: Mês | C70: Tipo de item de fluxo | D70: Descrição do item de fluxo | E70: Valor | F70: Abra quantas linhas necessitar, cuidando de não danificar a totalização
...

Sheet Capital de giro
C3: Curso Viabilidade de Projetos & Negócios – seleção de alternativas de investimento
B5: Capital de giro necessário
B7: Mês | C7: Vendas brutas | D7: Despesas variáveis | E7: Despesas fixas | F7: Resultado | G7: Saldo acumulado | I7: Despesas variáveis + fixas
B8: 1 | C8: ='Fluxo de caixa'!E31 -> 0 | D8: ='Fluxo de caixa'!E32 -> 310 | E8: ='Fluxo de caixa'!E33 -> 65 | F8: =C8-D8-E8 -> -375 | G8: =F8 -> -375 | I8: =D8+E8 -> 375
B9: 2 | C9: ='Fluxo de caixa'!E60 -> 400 | D9: ='Fluxo de caixa'!E61 -> 400 | E9: ='Fluxo de caixa'!E62 -> 65 | F9: =C9-D9-E9 -> -65 | G9: =G8+F9 -> -440 | I9: =D9+E9 -> 465
B10: 3 | C10: ='Fluxo de caixa'!E88 -> 500 | D10: ='Fluxo de caixa'!E89 -> 494 | E10: ='Fluxo de caixa'!E90 -> 65 | F10: =C10-D10-E10 -> -59 | G10: =G9+F10 -> -499 | I10: =D10+E10 -> 559
B11: 4 | C11: ='Fluxo de caixa'!E116 -> 700 | D11: ='Fluxo de caixa'!E117 -> 670 | E11: ='Fluxo de caixa'!E118 -> 65 | F11: =C11-D11-E11 -> -35 | G11: =G10+F11 -> -534 | I11: =D11+E11 -> 735
B12: 5 | C12: ='Fluxo de caixa'!E144 -> 1000 | D12: ='Fluxo de caixa'!E145 -> 931 | E12: ='Fluxo de caixa'!E146 -> 65 | F12: =C12-D12-E12 -> 4 | G12: =G11+F12 -> -530 | I12: =D12+E12 -> 996
B13: 6 | C13: ='Fluxo de caixa'!E172 -> 1300 | D13: ='Fluxo de caixa'!E173 -> 1130 | E13: ='Fluxo de caixa'!E174 -> 65 | F13: =C13-D13-E13 -> 105 | G13: =G12+F13 -> -425 | I13: =D13+E13 -> 1195
B14: 7 | C14: ='Fluxo de caixa'!E201 -> 1500 | D14: ='Fluxo de caixa'!E202 -> 1328 | E14: ='Fluxo de caixa'!E203 -> 65 | F14: =C14-D14-E14 -> 107 | G14: =G13+F14 -> -318 | I14: =D14+E14 -> 1393
B15: 8 | C15: ='Fluxo de caixa'!E229 -> 2000 | D15: ='Fluxo de caixa'!E230 -> 1640 | E15: ='Fluxo de caixa'!E231 -> 65 | F15: =C15-D15-E15 -> 295 | G15: =G14+F15 -> -23 | I15: =D15+E15 -> 1705
B16: 9 | C16: ='Fluxo de caixa'!E257 -> 2400 | D16: ='Fluxo de caixa'!E258 -> 2070 | E16: ='Fluxo de caixa'!E259 -> 65 | F16: =C16-D16-E16 -> 265 | G16: =G15+F16 -> 242 | I16: =D16+E16 -> 2135
B17: 10 | C17: ='Fluxo de caixa'!E285 -> 3000 | D17: ='Fluxo de caixa'!E286 -> 2744 | E17: ='Fluxo de caixa'!E287 -> 65 | F17: =C17-D17-E17 -> 191 | G17: =G16+F17 -> 433 | I17: =D17+E17 -> 2809
B18: 11 | C18: ='Fluxo de caixa'!E313 -> 3400 | D18: ='Fluxo de caixa'!E314 -> 3130 | E18: ='Fluxo de caixa'!E315 -> 65 | F18: =C18-D18-E18 -> 205 | G18: =G17+F18 -> 638 | I18: =D18+E18 -> 3195
B19: 12 | C19: ='Fluxo de caixa'!E342 -> 4500 | D19: ='Fluxo de caixa'!E343 -> 3744 | E19: ='Fluxo de caixa'!E344 -> 265 | F19: =C19-D19-E19 -> 491 | G19: =G18+F19 -> 1129 | I19: =D19+E19 -> 4009
B20: 13 | C20: ='Fluxo de caixa'!E370 -> 0 | D20: ='Fluxo de caixa'!E371 -> 0 | E20: ='Fluxo de caixa'!E372 -> 0 | F20: =C20-D20-E20 -> 0 | G20: =G19+F20 -> 1129
B21: 14 | C21: ='Fluxo de caixa'!E398 -> 0 | D21: ='Fluxo de caixa'!E399 -> 0 | E21: ='Fluxo de caixa'!E400 -> 0 | F21: =C21-D21-E21 -> 0 | G21: =G20+F21 -> 1129 | L21: Obs.: o ponto de equilíbrio é atingido quando a curva azul (de vendas brutas) cruza a curva laranja de total de depesas)
B22: 15 | C22: ='Fluxo de caixa'!E426 -> 0 | D22: ='Fluxo de caixa'!E427 -> 0 | E22: ='Fluxo de caixa'!E428 -> 0 | F22: =C22-D22-E22 -> 0 | G22: =G21+F22 -> 1129
B23: 16 | C23: ='Fluxo de caixa'!E454 -> 0 | D23: ='Fluxo de caixa'!E455 -> 0 | E23: ='Fluxo de caixa'!E456 -> 0 | F23: =C23-D23-E23 -> 0 | G23: =G22+F23 -> 1129
B24: 17 | C24: ='Fluxo de caixa'!E483 -> 0 | D24: ='Fluxo de caixa'!E484 -> 0 | E24: ='Fluxo de caixa'!E485 -> 0 | F24: =C24-D24-E24 -> 0 | G24: =G23+F24 -> 1129
B25: 18 | C25: ='Fluxo de caixa'!E511 -> 0 | D25: ='Fluxo de caixa'!E512 -> 0 | E25: ='Fluxo de caixa'!E513 -> 0 | F25: =C25-D25-E25 -> 0 | G25: =G24+F25 -> 1129
B26: 19 | C26: ='Fluxo de caixa'!E539 -> 0 | D26: ='Fluxo de caixa'!E540 -> 0 | E26: ='Fluxo de caixa'!E541 -> 0 | F26: =C26-D26-E26 -> 0 | G26: =G25+F26 -> 1129
B27: 20 | C27: ='Fluxo de caixa'!E567 -> 0 | D27: ='Fluxo de caixa'!E568 -> 0 | E27: ='Fluxo de caixa'!E569 -> 0 | F27: =C27-D27-E27 -> 0 | G27: =G26+F27 -> 1129
B28: 21 | C28: ='Fluxo de caixa'!E595 -> 0 | D28: ='Fluxo de caixa'!E596 -> 0 | E28: ='Fluxo de caixa'!E597 -> 0 | F28: =C28-D28-E28 -> 0 | G28: =G27+F28 -> 1129
B29: 22 | C29: ='Fluxo de caixa'!E624 -> 0 | D29: ='Fluxo de caixa'!E625 -> 0 | E29: ='Fluxo de caixa'!E626 -> 0 | F29: =C29-D29-E29 -> 0 | G29: =G28+F29 -> 1129
B30: 23 | C30: ='Fluxo de caixa'!E652 -> 0 | D30: ='Fluxo de caixa'!E653 -> 0 | E30: ='Fluxo de caixa'!E654 -> 0 | F30: =C30-D30-E30 -> 0 | G30: =G29+F30 -> 1129
B31: 24 | C31: ='Fluxo de caixa'!E680 -> 0 | D31: ='Fluxo de caixa'!E681 -> 0 | E31: ='Fluxo de caixa'!E682 -> 0 | F31: =C31-D31-E31 -> 0 | G31: =G30+F31 -> 1129

Sheet VPL e TIR
C3: Curso Viabilidade de Projetos & Negócios – seleção de alternativas de investimento
B5: Fluxo de caixa consolidado completo (para apuração de VPL e TIR)
B7: PERÍODO | C7: Investimentos | D7: Vendas brutas | E7: Despesas variáveis e fixas | F7: Recebimentos - Desembolsos | H7: Valor presente líquido (VPL) | J7: Taxa de juros por período
B8: 0 (presente) | C8: 400 | D8: 0 | E8: 0 | F8: =D8-C8-E8 -> -400 | H8: =F8/(1+J8/100)^0+F9/(1+J8/100)^1+F10/(1+J8/100)^2+F11/(1+J8/100)^3+F12/(1+J8/100)^4+F13/(1+J8/100)^5+F14/(1+J8/100)^6+F15/(1+J8/100)^7+F16/(1+J8/100)^8+F17/(1+J8/100)^9+F18/(1+J8/100)^10+F19/(1+J8/100)^11+F20/(1+J8/100)^12+F21/(1+J8/100)^13+F22/(1+J8/100)^14+F23/(1+J8/100)^15+F24/(1+J8/100)^16+F25/(1+J8/100)^17+ F26/(1+J8/100)^18+ F27/(1+J8/100)^19+F28/(1+J8/100)^20+ F29/(1+J8/100)^21+ F30/(1+J8/100)^22+ F31/(1+J8/100)^23+ F32/(1+J8/100)^24 -> 683.65285 | J8: 0.3 | K8: Ex.: Para 5,5%, digite 5,5
B9: Final do 1 | D9: ='Capital de giro'!C8 -> 0 | E9: ='Capital de giro'!D8+'Capital de giro'!E8 -> 375 | F9: =D9-C9-E9 -> -375
B10: Final do 2 | D10: ='Capital de giro'!C9 -> 400 | E10: ='Capital de giro'!D9+'Capital de giro'!E9 -> 465 | F10: =D10-C10-E10 -> -65 | H10: Para obter o VPL:
B11: Final do 3 | D11: ='Capital de giro'!C10 -> 500 | E11: ='Capital de giro'!D10+'Capital de giro'!E10 -> 559 | F11: =D11-C11-E11 -> -59 | H11: - Digite a taxa de juros por período na célula H8
B12: Final do 4 | D12: ='Capital de giro'!C11 -> 700 | E12: ='Capital de giro'!D11+'Capital de giro'!E11 -> 735 | F12: =D12-C12-E12 -> -35 | H12: - Seu fluxo de caixa está trazido no quadro ao lado - complemente com os aportes de investimentos
B13: Final do 5 | D13: ='Capital de giro'!C12 -> 1000 | E13: ='Capital de giro'!D12+'Capital de giro'!E12 -> 996 | F13: =D13-C13-E13 -> 4 | H13: - O VPL será exibido na célula H8
B14: Final do 6 | D14: ='Capital de giro'!C13 -> 1300 | E14: ='Capital de giro'!D13+'Capital de giro'!E13 -> 1195 | F14: =D14-C14-E14 -> 105
B15: Final do 7 | D15: ='Capital de giro'!C14 -> 1500 | E15: ='Capital de giro'!D14+'Capital de giro'!E14 -> 1393 | F15: =D15-C15-E15 -> 107 | H15: Para obter a TIR:
B16: Final do 8 | D16: ='Capital de giro'!C15 -> 2000 | E16: ='Capital de giro'!D15+'Capital de giro'!E15 -> 1705 | F16: =D16-C16-E16 -> 295 | H16: - Seu fluxo de caixa está trazido no quadro ao lado - complemente com os aportes de investimentos
B17: Final do 9 | D17: ='Capital de giro'!C16 -> 2400 | E17: ='Capital de giro'!D16+'Capital de giro'!E16 -> 2135 | F17: =D17-C17-E17 -> 265 | H17: - Vá ajustando a taxa de juros (célula J8) até o VPL (célula H8) ficar zerado ou muito próximo de zero
B18: Final do 10 | D18: ='Capital de giro'!C17 -> 3000 | E18: ='Capital de giro'!D17+'Capital de giro'!E17 -> 2809 | F18: =D18-C18-E18 -> 191 | H18: - Esta taxa será a TIR
B19: Final do 11 | D19: ='Capital de giro'!C18 -> 3400 | E19: ='Capital de giro'!D18+'Capital de giro'!E18 -> 3195 | F19: =D19-C19-E19 -> 205
B20: Final do 12 | D20: ='Capital de giro'!C19 -> 4500 | E20: ='Capital de giro'!D19+'Capital de giro'!E19 -> 4009 | F20: =D20-C20-E20 -> 491
B21: Final do 13 | D21: ='Capital de giro'!C20 -> 0 | E21: ='Capital de giro'!D20+'Capital de giro'!E20 -> 0 | F21: =D21-C21-E21 -> 0
B22: Final do 14 | D22: ='Capital de giro'!C21 -> 0 | E22: ='Capital de giro'!D21+'Capital de giro'!E21 -> 0 | F22: =D22-C22-E22 -> 0
B23: Final do 15 | D23: ='Capital de giro'!C22 -> 0 | E23: ='Capital de giro'!D22+'Capital de giro'!E22 -> 0 | F23: =D23-C23-E23 -> 0
B24: Final do 16 | D24: ='Capital de giro'!C23 -> 0 | E24: ='Capital de giro'!D23+'Capital de giro'!E23 -> 0 | F24: =D24-C24-E24 -> 0
B25: Final do 17 | D25: ='Capital de giro'!C24 -> 0 | E25: ='Capital de giro'!D24+'Capital de giro'!E24 -> 0 | F25: =D25-C25-E25 -> 0
B26: Final do 18 | D26: ='Capital de giro'!C25 -> 0 | E26: ='Capital de giro'!D25+'Capital de giro'!E25 -> 0 | F26: =D26-C26-E26 -> 0
B27: Final do 19 | D27: ='Capital de giro'!C26 -> 0 | E27: ='Capital de giro'!D26+'Capital de giro'!E26 -> 0 | F27: =D27-C27-E27 -> 0
B28: Final do 20 | D28: ='Capital de giro'!C27 -> 0 | E28: ='Capital de giro'!D27+'Capital de giro'!E27 -> 0 | F28: =D28-C28-E28 -> 0
B29: Final do 21 | D29: ='Capital de giro'!C28 -> 0 | E29: ='Capital de giro'!D28+'Capital de giro'!E28 -> 0 | F29: =D29-C29-E29 -> 0
B30: Final do 22 | D30: ='Capital de giro'!C29 -> 0 | E30: ='Capital de giro'!D29+'Capital de giro'!E29 -> 0 | F30: =D30-C30-E30 -> 0
... B32: Final do 24 | D32: ='Capital de giro'!C31 -> 0 | E32: ='Capital de giro'!D31+'Capital de giro'!E31 -> 0 | F32: =D32-C32-E32 -> 0

Sheet Impostos
C3: Curso Viabilidade de Projetos & Negócios – seleção de alternativas de investimento
C5: EMPRESA TRIBUTADA PELO LUCRO PRESUMIDO | O5: EMPRESA TRIBUTADA PELO SIMPLES
C7: (preencher os campos em laranja somente: % de impostos e valores GPS) | N7: (preencher os campos em laranja somente: alíquota nominal e parc. a deduzir)
C9: IRRF | D9: GPS PJ | E9: ISS | F9: PIS | G9: COFINS | H9: CSLL | I9: Total de impostos | O9: Alíquota (%): | P9: 6 | Q9: Parc. a deduzir: | R9: 0
B10: Vendas brutas | C10: 0.048 | D10: (*) | E10: 0.05 | F10: 0.0065 | G10: 0.03 | H10: 0.0288 | P10: Alíquota efetiva mês | Q10: Valor do imposto | R10: Rec. bruta 12
A11: 0 | B11: ='VPL e TIR'!D8 -> 0 | C11: =B11*$C$10 -> 0 | E11: =B11*$E$10 -> 0 | F11: =B11*$F$10 -> 0 | G11: =B11*$G$10 -> 0 | H11: =B11*$H$10 -> 0 | I11: =SUM(C11:H11) -> 0 | K11: (*) GPS pago mensalmente relativo | O11: 0 | P11: =((R11*($P$9/100))-$R$9)/R11 -> #DIV/0! | Q11: =P11*B11 -> #DIV/0! | R11: =B11 -> 0
A12: 1 | B12: ='VPL e TIR'!D9 -> 0 | C12: =B12*$C$10 -> 0 | E12: =B12*$E$10 -> 0 | F12: =B12*$F$10 -> 0 | G12: =B12*$G$10 -> 0 | H12: =B12*$H$10 -> 0 | I12: =SUM(C12:H12) -> 0 | K12: ao pró-labore dos sócios. | O12: 1 | P12: =((R12*($P$9/100))-$R$9)/R12 -> #DIV/0! | Q12: =P12*B12 -> #DIV/0! | R12: =SUM(B11:B12) -> 0
A13: 2 | B13: ='VPL e TIR'!D10 -> 400 | C13: =B13*$C$10 -> 19.2 | E13: =B13*$E$10 -> 20 | F13: =B13*$F$10 -> 2.6 | G13: =B13*$G$10 -> 12 | H13: =B13*$H$10 -> 11.52 | I13: =SUM(C13:H13) -> 65.32 | K13: Seu contador deve gerar a guia para | O13: 2 | P13: =((R13*($P$9/100))-$R$9)/R13 -> 0.06 | Q13: =P13*B13 -> 24 | R13: =SUM(B11:B13) -> 400
A14: 3 | B14: ='VPL e TIR'!D11 -> 500 | C14: =B14*$C$10 -> 24 | E14: =B14*$E$10 -> 25 | F14: =B14*$F$10 -> 3.25 | G14: =B14*$G$10 -> 15 | H14: =B14*$H$10 -> 14.4 | I14: =SUM(C14:H14) -> 81.65 | K14: você pagar todo dia 20. | O14: 3 | P14: =((R14*($P$9/100))-$R$9)/R14 -> 0.06 | Q14: =P14*B14 -> 30 | R14: =SUM(B11:B14) -> 900
A15: 4 | B15: ='VPL e TIR'!D12 -> 700 | C15: =B15*$C$10 -> 33.6 | E15: =B15*$E$10 -> 35 | F15: =B15*$F$10 -> 4.55 | G15: =B15*$G$10 -> 21 | H15: =B15*$H$10 -> 20.16 | I15: =SUM(C15:H15) -> 114.31 | K15: Preencha esta coluna com os valores. | O15: 4 | P15: =((R15*($P$9/100))-$R$9)/R15 -> 0.06 | Q15: =P15*B15 -> 42 | R15: =SUM(B11:B15) -> 1600
A16: 5 | B16: ='VPL e TIR'!D13 -> 1000 | C16: =B16*$C$10 -> 48 | E16: =B16*$E$10 -> 50 | F16: =B16*$F$10 -> 6.5 | G16: =B16*$G$10 -> 30 | H16: =B16*$H$10 -> 28.8 | I16: =SUM(C16:H16) -> 163.3 | O16: 5 | P16: =((R16*($P$9/100))-$R$9)/R16 -> 0.06 | Q16: =P16*B16 -> 60 | R16: =SUM(B11:B16) -> 2600
A17: 6 | B17: ='VPL e TIR'!D14 -> 1300 | C17: =B17*$C$10 -> 62.4 | E17: =B17*$E$10 -> 65 | F17: =B17*$F$10 -> 8.45 | G17: =B17*$G$10 -> 39 | H17: =B17*$H$10 -> 37.44 | I17: =SUM(C17:H17) -> 212.29 | O17: 6 | P17: =((R17*($P$9/100))-$R$9)/R17 -> 0.06 | Q17: =P17*B17 -> 78 | R17: =SUM(B11:B17) -> 3900
A18: 7 | B18: ='VPL e TIR'!D15 -> 1500 | C18: =B18*$C$10 -> 72 | E18: =B18*$E$10 -> 75 | F18: =B18*$F$10 -> 9.75 | G18: =B18*$G$10 -> 45 | H18: =B18*$H$10 -> 43.2 | I18: =SUM(C18:H18) -> 244.95 | O18: 7 | P18: =((R18*($P$9/100))-$R$9)/R18 -> 0.06 | Q18: =P18*B18 -> 90 | R18: =SUM(B11:B18) -> 5400
A19: 8 | B19: ='VPL e TIR'!D16 -> 2000 | C19: =B19*$C$10 -> 96 | E19: =B19*$E$10 -> 100 | F19: =B19*$F$10 -> 13 | G19: =B19*$G$10 -> 60 | H19: =B19*$H$10 -> 57.6 | I19: =SUM(C19:H19) -> 326.6 | K19: Atenção! | O19: 8 | P19: =((R19*($P$9/100))-$R$9)/R19 -> 0.06 | Q19: =P19*B19 -> 120 | R19: =SUM(B11:B19) -> 7400
A20: 9 | B20: ='VPL e TIR'!D17 -> 2400 | C20: =B20*$C$10 -> 115.2 | E20: =B20*$E$10 -> 120 | F20: =B20*$F$10 -> 15.6 | G20: =B20*$G$10 -> 72 | H20: =B20*$H$10 -> 69.12 | I20: =SUM(C20:H20) -> 391.92 | K20: Os tributos, suas alíquotas e regras | O20: 9 | P20: =((R20*($P$9/100))-$R$9)/R20 -> 0.06 | Q20: =P20*B20 -> 144 | R20: =SUM(B11:B20) -> 9800
A21: 10 | B21: ='VPL e TIR'!D18 -> 3000 | C21: =B21*$C$10 -> 144 | E21: =B21*$E$10 -> 150 | F21: =B21*$F$10 -> 19.5 | G21: =B21*$G$10 -> 90 | H21: =B21*$H$10 -> 86.4 | I21: =SUM(C21:H21) -> 489.9 | K21: de cálculo podem mudar em função | O21: 10 | P21: =((R21*($P$9/100))-$R$9)/R21 -> 0.06 | Q21: =P21*B21 -> 180 | R21: =SUM(B11:B21) -> 12800
A22: 11 | B22: ='VPL e TIR'!D19 -> 3400 | C22: =B22*$C$10 -> 163.2 | E22: =B22*$E$10 -> 170 | F22: =B22*$F$10 -> 22.1 | G22: =B22*$G$10 -> 102 | H22: =B22*$H$10 -> 97.92 | I22: =SUM(C22:H22) -> 555.22 | K22: das regras tributárias vigentes para | O22: 11 | P22: =((R22*($P$9/100))-$R$9)/R22 -> 0.06 | Q22: =P22*B22 -> 204 | R22: =SUM(B11:B22) -> 16200
A23: 12 | B23: ='VPL e TIR'!D20 -> 4500 | C23: =B23*$C$10 -> 216 | E23: =B23*$E$10 -> 225 | F23: =B23*$F$10 -> 29.25 | G23: =B23*$G$10 -> 135 | H23: =B23*$H$10 -> 129.6 | I23: =SUM(C23:H23) -> 734.85 | K23: o país e o enquadramento da sua | O23: 12 | P23: =((R23*($P$9/100))-$R$9)/R23 -> 0.06 | Q23: =P23*B23 -> 270 | R23: =SUM(B11:B23) -> 20700
A24: 13 | B24: ='VPL e TIR'!D21 -> 0 | C24: =B24*$C$10 -> 0 | E24: =B24*$E$10 -> 0 | F24: =B24*$F$10 -> 0 | G24: =B24*$G$10 -> 0 | H24: =B24*$H$10 -> 0 | I24: =SUM(C24:H24) -> 0 | K24: empresa. Converse com seu contador | O24: 13 | P24: =((R24*($P$9/100))-$R$9)/R24 -> 0.06 | Q24: =P24*B24 -> 0 | R24: =SUM(B12:B23) -> 20700
A25: 14 | B25: ='VPL e TIR'!D22 -> 0 | C25: =B25*$C$10 -> 0 | E25: =B25*$E$10 -> 0 | F25: =B25*$F$10 -> 0 | G25: =B25*$G$10 -> 0 | H25: =B25*$H$10 -> 0 | I25: =SUM(C25:H25) -> 0 | K25: para definir / confirmar esta | O25: 14 | P25: =((R25*($P$9/100))-$R$9)/R25 -> 0.06 | Q25: =P25*B25 -> 0 | R25: =SUM(B13:B24) -> 20700
A26: 15 | B26: ='VPL e TIR'!D23 -> 0 | C26: =B26*$C$10 -> 0 | E26: =B26*$E$10 -> 0 | F26: =B26*$F$10 -> 0 | G26: =B26*$G$10 -> 0 | H26: =B26*$H$10 -> 0 | I26: =SUM(C26:H26) -> 0 | K26: questão dos impostos. | O26: 15 | P26: =((R26*($P$9/100))-$R$9)/R26 -> 0.06 | Q26: =P26*B26 -> 0 | R26: =SUM(B14:B25) -> 20300
A27: 16 | B27: ='VPL e TIR'!D24 -> 0 | C27: =B27*$C$10 -> 0 | E27: =B27*$E$10 -> 0 | F27: =B27*$F$10 -> 0 | G27: =B27*$G$10 -> 0 | H27: =B27*$H$10 -> 0 | I27: =SUM(C27:H27) -> 0 | O27: 16 | P27: =((R27*($P$9/100))-$R$9)/R27 -> 0.06 | Q27: =P27*B27 -> 0 | R27: =SUM(B15:B26) -> 19800
A28: 17 | B28: ='VPL e TIR'!D25 -> 0 | C28: =B28*$C$10 -> 0 | E28: =B28*$E$10 -> 0 | F28: =B28*$F$10 -> 0 | G28: =B28*$G$10 -> 0 | H28: =B28*$H$10 -> 0 | I28: =SUM(C28:H28) -> 0 | K28: Parte dos tributos pode ter | O28: 17 | P28: =((R28*($P$9/100))-$R$9)/R28 -> 0.06 | Q28: =P28*B28 -> 0 | R28: =SUM(B16:B27) -> 19100
A29: 18 | B29: ='VPL e TIR'!D26 -> 0 | C29: =B29*$C$10 -> 0 | E29: =B29*$E$10 -> 0 | F29: =B29*$F$10 -> 0 | G29: =B29*$G$10 -> 0 | H29: =B29*$H$10 -> 0 | I29: =SUM(C29:H29) -> 0 | K29: retenção na fonte e pode haver | O29: 18 | P29: =((R29*($P$9/100))-$R$9)/R29 -> 0.06 | Q29: =P29*B29 -> 0 | R29: =SUM(B17:B28) -> 18100
A30: 19 | B30: ='VPL e TIR'!D27 -> 0 | C30: =B30*$C$10 -> 0 | E30: =B30*$E$10 -> 0 | F30: =B30*$F$10 -> 0 | G30: =B30*$G$10 -> 0 | H30: =B30*$H$10 -> 0 | I30: =SUM(C30:H30) -> 0 | K30: pagamentos trimestrais de | O30: 19 | P30: =((R30*($P$9/100))-$R$9)/R30 -> 0.06 | Q30: =P30*B30 -> 0 | R30: =SUM(B18:B29) -> 16800
A31: 20 | B31: ='VPL e TIR'!D28 -> 0 | C31: =B31*$C$10 -> 0 | E31: =B31*$E$10 -> 0 | F31: =B31*$F$10 -> 0 | G31: =B31*$G$10 -> 0 | H31: =B31*$H$10 -> 0 | I31: =SUM(C31:H31) -> 0 | K31: diferenças. Informe-se com seu | O31: 20 | P31: =((R31*($P$9/100))-$R$9)/R31 -> 0.06 | Q31: =P31*B31 -> 0 | R31: =SUM(B19:B30) -> 15300
A32: 21 | B32: ='VPL e TIR'!D29 -> 0 | C32: =B32*$C$10 -> 0 | E32: =B32*$E$10 -> 0 | F32: =B32*$F$10 -> 0 | G32: =B32*$G$10 -> 0 | H32: =B32*$H$10 -> 0 | I32: =SUM(C32:H32) -> 0 | K32: contador de confiança! | O32: 21 | P32: =((R32*($P$9/100))-$R$9)/R32 -> 0.06 | Q32: =P32*B32 -> 0 | R32: =SUM(B20:B31) -> 13300
A33: 22 | B33: ='VPL e TIR'!D30 -> 0 | C33: =B33*$C$10 -> 0 | E33: =B33*$E$10 -> 0 | F33: =B33*$F$10 -> 0 | G33: =B33*$G$10 -> 0 | H33: =B33*$H$10 -> 0 | I33: =SUM(C33:H33) -> 0 | O33: 22 | P33: =((R33*($P$9/100))-$R$9)/R33 -> 0.06 | Q33: =P33*B33 -> 0 | R33: =SUM(B21:B32) -> 10900
A34: 23 | B34: ='VPL e TIR'!D31 -> 0 | C34: =B34*$C$10 -> 0 | E34: =B34*$E$10 -> 0 | F34: =B34*$F$10 -> 0 | G34: =B34*$G$10 -> 0 | H34: =B34*$H$10 -> 0 | I34: =SUM(C34:H34) -> 0 | O34: 23 | P34: =((R34*($P$9/100))-$R$9)/R34 -> 0.06 | Q34: =P34*B34 -> 0 | R34: =SUM(B22:B33) -> 7900
A35: 24 | B35: ='VPL e TIR'!D32 -> 0 | C35: =B35*$C$10 -> 0 | E35: =B35*$E$10 -> 0 | F35: =B35*$F$10 -> 0 | G35: =B35*$G$10 -> 0 | H35: =B35*$H$10 -> 0 | I35: =SUM(C35:H35) -> 0 | O35: 24 | P35: =((R35*($P$9/100))-$R$9)/R35 -> 0.06 | Q35: =P35*B35 -> 0 | R35: =SUM(B23:B34) -> 4500

Sheet Alternativas - P desconhecidas
D3: Curso Viabilidade de Projetos & Negócios – seleção de alternativas de investimento
C5: SELEÇÃO DE ALTERNATIVAS - PROBABILIDADES DESCONHECIDAS
C7: Caso 1 = valores de resultados são bons quando maximizados (exemplo: lucro)
D9: (preencher os campos em laranja somente: valores de resultados e fator de otimismo)
D11: Resultado 1 | E11: Resultado 2 | F11: Resultado 3 | G11: Resultado 4 | H11: Mínimo (pior) | I11: Máximo (melhor) | J11: Hurwicz | K11: Laplace
C12: Alternativa A | D12: 12000 | E12: 19000 | F12: 19000 | G12: 20000 | H12: =MIN(D12:G12) -> 12000 | I12: =MAX(D12:G12) -> 20000 | J12: =$M$18*I12+(1-$M$18)*H12 -> 14000 | K12: =AVERAGE(D12:G12) -> 17500
C13: Alternativa B | D13: 14000 | E13: 14000 | F13: 14000 | G13: 14000 | H13: =MIN(D13:G13) -> 14000 | I13: =MAX(D13:G13) -> 14000 | J13: =$M$18*I13+(1-$M$18)*H13 -> 14000 | K13: =AVERAGE(D13:G13) -> 14000
C14: Alternativa C | D14: 13000 | E14: 10000 | F14: 22000 | G14: 13000 | H14: =MIN(D14:G14) -> 10000 | I14: =MAX(D14:G14) -> 22000 | J14: =$M$18*I14+(1-$M$18)*H14 -> 13000 | K14: =AVERAGE(D14:G14) -> 14500
C15: Alternativa D | D15: 21000 | E15: 18000 | F15: 13000 | G15: 14000 | H15: =MIN(D15:G15) -> 13000 | I15: =MAX(D15:G15) -> 21000 | J15: =$M$18*I15+(1-$M$18)*H15 -> 15000 | K15: =AVERAGE(D15:G15) -> 16500
G16: MAXIMIN | H16: =MAX(H12:H15) -> 14000
H17: MAXIMAX | I17: =MAX(I12:I15) -> 22000
H18: MELHOR VALOR HURWICZ | J18: =MAX(J12:J15) -> 15000 | K18: Fator de otimismo: | M18: 0.25 | N18: (0,00 a 1,00)
I19: MELHOR VALOR LAPLACE | K19: =MAX(K12:K15) -> 17500
C21: Caso 2 = valores de resultados são bons quando minimizados (exemplo: custo)
D23: Resultado 1 | E23: Resultado 2 | F23: Resultado 3 | G23: Resultado 4 | H23: Máximo (pior) | I23: Mínimo (melhor) | J23: Hurwicz | K23: Laplace
C24: Alternativa A | D24: 12000 | E24: 19000 | F24: 19000 | G24: 20000 | H24: =MAX(D24:G24) -> 20000 | I24: =MIN(D24:G24) -> 12000 | J24: =$M$30*I24+(1-$M$30)*H24 -> 18000 | K24: =AVERAGE(D24:G24) -> 17500 | M24: Não copíe e cole valores de resultados do quadro acima (Caso 1) para este abaixo (Caso 2)
C25: Alternativa B | D25: 14000 | E25: 14000 | F25: 14000 | G25: 14000 | H25: =MAX(D25:G25) -> 14000 | I25: =MIN(D25:G25) -> 14000 | J25: =$M$30*I25+(1-$M$30)*H25 -> 14000 | K25: =AVERAGE(D25:G25) -> 14000
C26: Alternativa C | D26: 13000 | E26: 10000 | F26: 22000 | G26: 13000 | H26: =MAX(D26:G26) -> 22000 | I26: =MIN(D26:G26) -> 10000 | J26: =$M$30*I26+(1-$M$30)*H26 -> 19000 | K26: =AVERAGE(D26:G26) -> 14500
C27: Alternativa D | D27: 21000 | E27: 18000 | F27: 13000 | G27: 14000 | H27: =MAX(D27:G27) -> 21000 | I27: =MIN(D27:G27) -> 13000 | J27: =$M$30*I27+(1-$M$30)*H27 -> 19000 | K27: =AVERAGE(D27:G27) -> 16500
G28: MINIMAX | H28: =MIN(H24:H27) -> 14000
H29: MINIMIN | I29: =MIN(I24:I27) -> 10000
H30: MELHOR VALOR HURWICZ | J30: =MIN(J24:J27) -> 14000 | K30: Fator de otimismo: | M30: 0.25 | N30: (0,00 a 1,00)
I31: MELHOR VALOR LAPLACE | K31: =MIN(K24:K27) -> 14000
